Workbook

Sheet Plan de Pago Semanal
A1: DEEPCOMPANY — Plan de Pago Semanal (martes)
A2: Sueldos repartidos en 4 cortes semanales. Incluye consolidado con beneficios (fideicomisos, seguro, formaciones, beca, IA).
A4: Consolidado por semana
C5: Semana 1 (Prod/Proy/Legal) | D5: Semana 2 (Admin/Sop/Campo) | E5: Semana 3 (Dirección) | F5: Semana 4 (Mktg/Operac.) | G5: TOTAL MES
A6: Nómina | C6: =SUM('Nómina por persona'!F5:F24) -> 4000 | D6: =SUM('Nómina por persona'!G5:G24) -> 4225 | E6: =SUM('Nómina por persona'!H5:H24) -> 4245 | F6: =SUM('Nómina por persona'!I5:I24) -> 4975 | G6: =SUM(C6:F6) -> 17445
A7: Beneficios y otros | C7: =SUMIF('Beneficios y Otros Costos'!$F$5:$F$10,1,'Beneficios y Otros Costos'!$E$5:$E$10) -> 0 | D7: =SUMIF('Beneficios y Otros Costos'!$F$5:$F$10,2,'Beneficios y Otros Costos'!$E$5:$E$10) -> 0 | E7: =SUMIF('Beneficios y Otros Costos'!$F$5:$F$10,3,'Beneficios y Otros Costos'!$E$5:$E$10) -> 0 | F7: =SUMIF('Beneficios y Otros Costos'!$F$5:$F$10,4,'Beneficios y Otros Costos'!$E$5:$E$10) -> 0 | G7: =SUM(C7:F7) -> 0
A8: TOTAL semanal | C8: =SUM(C6:C7) -> 4000 | D8: =SUM(D6:D7) -> 4225 | E8: =SUM(E6:E7) -> 4245 | F8: =SUM(F6:F7) -> 4975 | G8: =SUM(G6:G7) -> 17445
A9: Solo nómina — rango | C9: =TEXT(MIN(C6:F6),"$#,##0")&" – "&TEXT(MAX(C6:F6),"$#,##0") -> $4000,0 – $4975,0
A11: SEMANA 1 · Producto · Proyectos · Legal | D11: =SUM('Nómina por persona'!F5:F24) -> 4000
A12: Empleado | B12: Fecha de ingreso | C12: Rol | D12: Monto (USD)
A13: Roger Hernandez | B13: 45658 | C13: CEO | D13: ='Nómina por persona'!F5 -> 1500
A14: Roger Hernandez G | B14: 46023 | C14: Asistente de Proyectos | D14: ='Nómina por persona'!F6 -> 200
A15: Victor Mendoza | B15: 45658 | C15: Líder de Campo (Caracas) | D15: ='Nómina por persona'!F7 -> 450
A16: Franklin Gonzalez | B16: 45658 | C16: Técnico de Campo (Caracas) | D16: ='Nómina por persona'!F8 -> 400
A17: Jean Paul Hernandez | B17: 45811 | C17: Coordinador de Soporte | D17: ='Nómina por persona'!F9 -> 450
A18: Edbin Fernandez | B18: 46023 | C18: Programador / CTO | D18: ='Nómina por persona'!F10 -> 1000
A20: SEMANA 2 · Administración · Contabilidad · Soporte · Campo | D20: =SUM('Nómina por persona'!G5:G24) -> 4225
A21: Empleado | B21: Fecha de ingreso | C21: Rol | D21: Monto (USD)
A22: Noribel Mendoza | B22: 46034 | C22: Asistente administrativa | D22: ='Nómina por persona'!G11 -> 400
A23: Roger Hernandez | B23: 46023 | C23: CEO | D23: ='Nómina por persona'!G5 -> 1500
A24: Edbin Fernandez | B24: 46023 | C24: Programador / CTO | D24: ='Nómina por persona'!G10 -> 1000
A25: Vacante | C25: Técnico de Campo (Valencia) | D25: ='Nómina por persona'!G12 -> 175
A26: Carlos | B26: 46181 | C26: Técnico de Campo (Barquisimeto) | D26: ='Nómina por persona'!G13 -> 175
A27: Gabriel Hernandez | B27: 46118 | C27: Programador Electrónico | D27: ='Nómina por persona'!G14 -> 400
A28: Kevin Kilson | B28: 46097 | C28: Coordinador de Operaciones | D28: ='Nómina por persona'!G15 -> 400
A29: Luis Burgos | B29: 45834 | C29: Vendedor | D29: ='Nómina por persona'!G16 -> 175
A31: SEMANA 3 · Dirección | D31: =SUM('Nómina por persona'!H5:H24) -> 4245
A32: Empleado | B32: Fecha de ingreso | C32: Rol | D32: Monto (USD)
A33: Roderick Bompart | B33: 46155 | C33: Programador Líder | D33: ='Nómina por persona'!H17 -> 1260
A34: Laila Escalante | C34: Aprendiz Administrativo | D34: ='Nómina por persona'!H18 -> 135
A35: Juan Roby | B35: 46023 | C35: Outsourcing contrataciones | D35: ='Nómina por persona'!H19 -> 350
A36: Naxely Osuna | B36: 46168 | C36: Product Owner UX/UI | D36: ='Nómina por persona'!H20 -> 1000
A37: Roger Hernandez | B37: 46023 | C37: CEO | D37: ='Nómina por persona'!H5 -> 1500
A39: SEMANA 4 · Marketing · Operaciones | D39: =SUM('Nómina por persona'!I5:I24) -> 4975
A40: Empleado | B40: Fecha de ingreso | C40: Rol | D40: Monto (USD)
A41: Elayne Escalante | B41: 46023 | C41: Coordinadora de ventas | D41: ='Nómina por persona'!I21 -> 1500
A42: Luis Burgos | B42: 45834 | C42: Vendedor | D42: ='Nómina por persona'!I16 -> 175
A43: Vacante | C43: Coordinador de Marketing | D43: ='Nómina por persona'!I22 -> 1000
A44: Gabriel Hernandez | B44: 46118 | C44: Programador Electrónico | D44: ='Nómina por persona'!I14 -> 400
A45: Vacante | C45: Técnico de Campo (Valencia) | D45: ='Nómina por persona'!I12 -> 175
...

Sheet Nómina por persona
A1: Nómina por persona — base mensual y reparto por semana
A2: Celdas azules (Semana 1–4) son editables. El monto mensual y los pagos/mes se calculan solos, y el Plan se actualiza automáticamente.
A4: Departamento | B4: Empleado | C4: Rol | D4: Estado | E4: Monto mensual (USD) | F4: Semana 1 | G4: Semana 2 | H4: Semana 3 | I4: Semana 4 | J4: Pagos /mes
A5: Dirección | B5: Roger Hernandez | C5: CEO | D5: Activo | E5: =SUM(F5:I5) -> 4500 | F5: 1500 | G5: 1500 | H5: 1500 | J5: =COUNTIF(F5:I5,">0") -> 3
A6: Proyectos y Fabricación | B6: Roger Hernandez G | C6: Asistente de Proyectos | D6: Activo | E6: =SUM(F6:I6) -> 200 | F6: 200 | J6: =COUNTIF(F6:I6,">0") -> 1
A7: Campo | B7: Victor Mendoza | C7: Líder de Campo (Caracas) | D7: Activo | E7: =SUM(F7:I7) -> 450 | F7: 450 | J7: =COUNTIF(F7:I7,">0") -> 1
A8: Campo | B8: Franklin Gonzalez | C8: Técnico de Campo (Caracas) | D8: Activo | E8: =SUM(F8:I8) -> 400 | F8: 400 | J8: =COUNTIF(F8:I8,">0") -> 1
A9: Soporte y Atención | B9: Jean Paul Hernandez | C9: Coordinador de Soporte | D9: Activo | E9: =SUM(F9:I9) -> 450 | F9: 450 | J9: =COUNTIF(F9:I9,">0") -> 1
A10: Soporte y Atención | B10: Edbin Fernandez | C10: Programador / CTO | D10: Activo | E10: =SUM(F10:I10) -> 2000 | F10: 1000 | G10: 1000 | J10: =COUNTIF(F10:I10,">0") -> 2
A11: Administración y Finanza | B11: Noribel Mendoza | C11: Asistente administrativa | D11: Activo | E11: =SUM(F11:I11) -> 400 | G11: 400 | J11: =COUNTIF(F11:I11,">0") -> 1
A12: Campo | B12: Vacante | C12: Técnico de Campo (Valencia) | D12: A contratar | E12: =SUM(F12:I12) -> 350 | G12: 175 | I12: 175 | J12: =COUNTIF(F12:I12,">0") -> 2
A13: Campo | B13: Carlos | C13: Técnico de Campo (Barquisimeto) | D13: Activo | E13: =SUM(F13:I13) -> 350 | G13: 175 | I13: 175 | J13: =COUNTIF(F13:I13,">0") -> 2
A14: Producto y Desarrollo | B14: Gabriel Hernandez | C14: Programador Electrónico | D14: Activo | E14: =SUM(F14:I14) -> 800 | G14: 400 | I14: 400 | J14: =COUNTIF(F14:I14,">0") -> 2
A15: Operaciones y RRHH | B15: Kevin Kilson | C15: Coordinador de Operaciones | D15: Activo | E15: =SUM(F15:I15) -> 800 | G15: 400 | I15: 400 | J15: =COUNTIF(F15:I15,">0") -> 2
A16: Marketing y Ventas | B16: Luis Burgos | C16: Vendedor | D16: Activo | E16: =SUM(F16:I16) -> 350 | G16: 175 | I16: 175 | J16: =COUNTIF(F16:I16,">0") -> 2
A17: Producto y Desarrollo | B17: Roderick Bompart | C17: Programador Líder | D17: Activo | E17: =SUM(F17:I17) -> 1260 | H17: 1260 | J17: =COUNTIF(F17:I17,">0") -> 1
A18: Administración y Finanza | B18: Laila Escalante | C18: Aprendiz Administrativo | D18: Activo | E18: =SUM(F18:I18) -> 135 | H18: 135 | J18: =COUNTIF(F18:I18,">0") -> 1
A19: Legal | B19: Juan Roby | C19: Outsourcing contrataciones | D19: Activo | E19: =SUM(F19:I19) -> 350 | H19: 350 | J19: =COUNTIF(F19:I19,">0") -> 1
A20: Producto y Desarrollo | B20: Naxely Osuna | C20: Product Owner UX/UI | D20: Activo | E20: =SUM(F20:I20) -> 1000 | H20: 1000 | J20: =COUNTIF(F20:I20,">0") -> 1
A21: Marketing y Ventas | B21: Elayne Escalante | C21: Coordinadora de ventas | D21: Activo | E21: =SUM(F21:I21) -> 1500 | I21: 1500 | J21: =COUNTIF(F21:I21,">0") -> 1
A22: Marketing y Ventas | B22: Vacante | C22: Coordinador de Marketing | D22: Vacante | E22: =SUM(F22:I22) -> 1000 | I22: 1000 | J22: =COUNTIF(F22:I22,">0") -> 1
A23: Producto y Desarrollo | B23: Marielby | C23: UX/UI | D23: Activo | E23: =SUM(F23:I23) -> 350 | I23: 350 | J23: =COUNTIF(F23:I23,">0") -> 1
A24: Proyectos y Fabricación | B24: Wilver Freites | C24: Líder de proyectos | D24: Activo | E24: =SUM(F24:I24) -> 800 | I24: 800 | J24: =COUNTIF(F24:I24,">0") -> 1
A25: TOTAL | E25: =SUM(E5:E24) -> 17445 | F25: =SUM(F5:F24) -> 4000 | G25: =SUM(G5:G24) -> 4225 | H25: =SUM(H5:H24) -> 4245 | I25: =SUM(I5:I24) -> 4975

Sheet Beneficios y Otros Costos
A1: Beneficios y Otros Costos — fideicomisos, seguro, formaciones, beca, IA
A2: Rellena las celdas amarillas (montos, tasa Bs y semana de pago). El equivalente en USD y el consolidado se calculan solos.
A4: Concepto | B4: Monto mensual | C4: Moneda | D4: Tasa (Bs/USD) | E4: Equivalente USD | F4: Semana de pago | G4: Frecuencia | H4: Notas
A5: Fideicomiso en dólares | B5: 1395.6 | C5: USD | D5: — | E5: =IF(C5="Bs",IF(D5>0,B5/D5,0),B5) -> 1395.6 | G5: Mensual | H5: Aporte mensual al fideicomiso en USD
A6: Fideicomiso en Bolívares | B6: 156 | C6: Bs | D6: 570 | E6: =IF(C6="Bs",IF(D6>0,B6/D6,0),B6) -> 0.27368421 | G6: Mensual | H6: Monto en Bs; se convierte a USD con la tasa indicada
A7: Seguro | B7: 0 | C7: USD | D7: — | E7: =IF(C7="Bs",IF(D7>0,B7/D7,0),B7) -> 0 | G7: Mensual | H7: Pólizas HCM / seguro del equipo
A8: Formaciones | B8: 0 | C8: USD | D8: — | E8: =IF(C8="Bs",IF(D8>0,B8/D8,0),B8) -> 0 | G8: Mensual | H8: Presupuesto de formación / capacitación
A9: Beca corporativa | B9: 0 | C9: USD | D9: — | E9: =IF(C9="Bs",IF(D9>0,B9/D9,0),B9) -> 0 | G9: Mensual | H9: Beca de estudios (p. ej. aprendiz)
A10: Cuenta AI | B10: 0 | C10: USD | D10: — | E10: =IF(C10="Bs",IF(D10>0,B10/D10,0),B10) -> 0 | G10: Mensual | H10: Suscripciones de IA (Claude, etc.)
A11: TOTAL (USD) | E11: =SUM(E5:E10) -> 1395.8737
